Workbook

Sheet Rules
A1: IRC Section | B1: Plain English Summary | C1: Affects Industry | D1: Affects Entity Type | E1: QuickBooks Data Needed | F1: Alert Message Template | G1: Non-Accountant Explanation
A2: §168 | B2: (k)Special allowance for certain property (1)Additional allowance In the case of any qualified property— (A)the depreciation deduction provided by section 167(a) for the taxable year in which such property is placed in service shall include an allowance equal to 100 percent of the adjusted basis of the qualified property, and (B)the adjusted basis of the qualified property shall be reduced by the amount of such deduction before computing the amount otherwise allowable as a depreciation deduction under this chapter for such taxable year and any subsequent taxable year. (2)Qualified property For purposes of this subsection— (A)In general The term “qualified property” means property— (i) (I)to which this section applies which has a recovery period of 20 years or less, (II)which is computer software (as defined in section 167(f)(1)(B)) for which a deduction is allowable under section 167(a) without regard to this subsection, (III)which is water utility property, or [2] (IV)which is a qualified film or television production (as defined in subsection (d) of section 181) for which a deduction would have been allowable under section 181 without regard to subsections (a)(2) and (h) of such section or this subsection, (V)which is a qualified live theatrical production (as defined in subsection (e) of section 181) for which a deduction would have been allowable under section 181 without regard to subsections (a)(2) and (h) of such section or this subsection, and or [3] (VI)which is a qualified sound recording production (as defined in subsection (f) of section 181) for which a deduction would have been allowable under section 181 without regard to subsections (a)(2) and (h) of such section or this subsection, and (ii)the original use of which begins with the taxpayer or the acquisition of which by the taxpayer meets the requirements of clause (i) of subparagraph (E). (B)Certain property having longer production periods treated as qualified property (i)In general The term “qualified property” includes any property if such property— (I)meets the requirements of clauses (i) and (ii) of subparagraph (A), (II)has a recovery period of at least 10 years or is transportation property, (III)is subject to section 263A, and (IV)meets the requirements of clause (iii) of section 263A(f)(1)(B) (determined as if such clause also applies to property which has a long useful life (within the meaning of section 263A(f))). (ii)Transportation property For purposes of this subparagraph, the term “transportation property” means tangible personal property used in the trade or business of transporting persons or property. (iii)Application of subparagraph This subparagraph shall not apply to any property which is described in subparagraph (C). (C)Certain aircraft The term “qualified property” includes property— (i)which meets the requirements of subparagraph (A)(ii), (ii)which is an aircraft which is not a transportation property (as defined in subparagraph (B)(ii)) other than for agricultural or firefighting purposes, (iii)which is purchased and on which such purchaser, at the time of the contract for purchase, has made a nonrefundable deposit of the lesser of— (I)10 percent of the cost, or (II)$100,000, and (iv)which has— (I)an estimated production period exceeding 4 months, and (II)a cost exceeding $200,000. (D)Exception for alternative depreciation property The term “qualified property” shall not include any property to which the alternative depreciation system under subsection (g) applies, determined— (i)without regard to paragraph (7) of subsection (g) (relating to election to have system apply), and (ii)after application of section 280F(b) (relating to listed property with limited business use). (E)Special rules (i)Acquisition requirements An acquisition of property meets the requirements of this clause if— (I)such property was not used by the taxpayer at any time prior to such acquisition, and (II)the acquisition of such property meets the requirements of paragraphs (2)(A), (2)(B), (2)(C), and (3) of section 179(d). (ii)Syndication For purposes of subparagraph (A)(ii), if— (I)property is used by a lessor of such property and such use is the lessor’s first use of such property, (II)such property is sold by such lessor or any subsequent purchaser within 3 months after the date such property was originally placed in service (or, in the case of multiple units of property subject to the same lease, within 3 months after the date the final unit is placed in service, so long as the period between the time the first unit is placed in service and the time the last unit is placed in service does not exceed 12 months), and (III)the user of such property after the last sale during such 3-month period remains the same as when such property was originally placed in service, such property shall be treated as originally placed in service not earlier than the date of such last sale. (F)Coordination with section 280F For purposes of section 280F— (i)Automobiles In the case of a passenger automobile (as defined in section 280F(d)(5)) which is qualified property, the Secretary shall increase the limitation under section 280F(a)(1)(A)(i) by $8,000. (ii)Listed property The deduction allowable under paragraph (1) shall be taken into account in computing any recapture amount under section 280F(b)(2). (iii)Phase down In the case of a passenger automobile acquired by the taxpayer before September 28, 2017, and placed in service by the taxpayer after September 27, 2017, clause (i) shall be applied by substituting for “$8,000”— (I)in the case of an automobile placed in service during 2018, $6,400, and (II)in the case of an automobile placed in service during 2019, $4,800. (G)Deduction allowed in computing minimum tax For purposes of determining alternative minimum taxable income under section 55, the deduction under section 167 for qualified property shall be determined without regard to any adjustment under section 56. (H)Production placed in service For purposes of subparagraph (A)— (i)a qualified film or television production shall be considered to be placed in service at the time of initial release or broadcast, (ii)a qualified live theatrical production shall be considered to be placed in service at the time of the initial live staged performance, and (iii)a qualified sound recording production shall be considered to be placed in service at the time of initial release or broadcast. [(3)Repealed. Pub. L. 115–97, title I, § 13204(a)(4)(B)(ii), Dec. 22, 2017, 131 Stat. 2111] [(4)Repealed. Pub. L. 115–97, title I, § 12001(b)(13), Dec. 22, 2017, 131 Stat. 2094] (5)Special rules for certain plants bearing fruits and nuts (A)In general In the case of any specified plant which is planted or grafted by the taxpayer in the ordinary course of the taxpayer’s farming business (as defined in section 263A(e)(4)) during a taxable year for which the taxpayer has elected the application of this paragraph— (i)a depreciation deduction equal to 100 percent of the adjusted basis of such specified plant shall be allowed under section 167(a) for the taxable year in which such specified plant is so planted or grafted, and (ii)the adjusted basis of such specified plant shall be reduced by the amount of such deduction. (B)Specified plant For purposes of this paragraph, the term “specified plant” means— (i)any tree or vine which bears fruits or nuts, and (ii)any other plant which will have more than one crop or yield of fruits or nuts and which generally has a pre-productive period of more than 2 years from the time of planting or grafting to the time at which such plant begins bearing a marketable crop or yield of fruits or nuts. Such term shall not include any property which is planted or grafted outside of the United States. (C)Election revocable only with consent An election under this paragraph may be revoked only with the consent of the Secretary. (D)Additional depreciation may be claimed only once If this paragraph applies to any specified plant, such specified plant shall not be treated as qualified property in the taxable year in which placed in service. (E)Deduction allowed in computing minimum tax Rules similar to the rules of paragraph (2)(G) shall apply for purposes of this paragraph. [(6)Repealed. Pub. L. 119–21, title VII, § 70301(b)(1)(B), July 4, 2025, 139 Stat. 189] (7)Election out If a taxpayer makes an election under this paragraph with respect to any class of property for any taxable year, paragraphs (1) and (2)(F) shall not apply to any qualified property in such class placed in service during such taxable year. An election under this paragraph may be revoked only with the consent of the Secretary. [(8)Repealed. Pub. L. 119–21, title VII, § 70301(b)(1)(B), July 4, 2025, 139 Stat. 189] (9)Exception for certain property The term “qualified property” shall not include— (A)any property which is primarily used in a trade or business described in clause (iv) of section 163(j)(7)(A), or (B)any property used in a trade or business that has had floor plan financing indebtedness (as defined in paragraph (9) of section 163(j)), if the floor plan financing interest related to such indebtedness was taken into account under paragraph (1)(C) of such section. (10)Special rule for property placed in service during certain periods (A)In general In the case of qualified property placed in service by the taxpayer during the first taxable year ending after January 19, 2025, if the taxpayer elects to have this paragraph apply for such taxable year, paragraph (1)(A) shall be applied— (i)in the case of property which is not described in clause (ii), by substituting “40 percent” for “100 percent”, or (ii)in the case of property which is described in subparagraph (B) or (C) of paragraph (2), by substituting “60 percent” for “100 percent”. (B)Specified plants In the case of any specified plant planted or grafted by the taxpayer during the first taxable year ending after January 19, 2025, if the taxpayer elects to have this paragraph apply for such taxable year, paragraph (5)(A)(i) shall be applied by substituting “40 percent” for “100 percent”. (C)Form of election Any election under this paragraph shall be made at such time and in such form and manner as the Secretary may prescribe. | C2: =IFERROR(__xludf.DUMMYFUNCTION("GEMINI(""Summarize this IRC legal text in exactly 1 sentence for a non-tax professional. Keep it under 20 words. Text: ""&B2)"),"Businesses can immediately deduct 100% of the cost of certain qualified property in the first year.") -> Businesses can immediately deduct 100% of the cost of certain qualified property in the first year. | D2: =IFERROR(__xludf.DUMMYFUNCTION("GEMINI(""Based on this IRC rule, list 3-5 industries and 2-3 entity types this affects. Format as: Industries: [x,y,z] | Entities: [a,b,c]. Text: ""&B2)"),"Industries: [Motion Picture and Video, Sound Recording, Performing Arts, Agriculture, Transportation] | Entities: [Corporations, Limited Liability Companies, Partnerships]") -> Industries: [Motion Picture and Video, Sound Recording, Performing Arts, Agriculture, Transportation] | Entities: [Corporations, Limited Liability Companies, Partnerships] | E2: =IFERROR(__xludf.DUMMYFUNCTION("GEMINI(""What specific QuickBooks data fields must be checked to see if this IRC rule applies to a business? List them as comma-separated account names or report fields. Text: ""&B2)"),"Fixed Asset Accounts, Purchase Date, Asset Description, Original Cost, Accumulated Depreciation, Section 179/Bonus Depreciation Election, Chart of Accounts (for business type and floor plan financing interest), Vehicle Log (for 280F compliance), Item List"&" (for computer software or media productions)") -> Fixed Asset Accounts, Purchase Date, Asset Description, Original Cost, Accumulated Depreciation, Section 179/Bonus Depreciation Election, Chart of Accounts (for business type and floor plan financing interest), Vehicle Log (for 280F compliance), Item List (for computer software or media productions) | F2: 🚨 Important: 100% Bonus Depreciation Restoration for [Entity] How this affects you: Great news for [Date]\! Under the newly restored provisions of IRC Section 168(k), your business can now immediately deduct 100% of the cost of qualified property placed in service after January 19, 2025. This allows [Entity] to write off the full [Amount] of eligible investments—such as machinery, equipment, computer software, and certain vehicles—in a single year rather than over a standard depreciation schedule, significantly reducing your taxable income and improving immediate cash flow. ✅ Verify that the property meets the "original use" requirement or was newly acquired by your business ✅ Ensure the assets have a recovery period of 20 years or less to qualify for the full deduction ✅ Update your QuickBooks fixed asset records to reflect the 100% first-year allowance election 📚 Source: IRC Section 168 ⚠️ Disclaimer: This template is for informational purposes only. Tax laws are subject to change and eligibility criteria for qualified property are complex. Please consult with a qualified tax professional to confirm compliance for your specific situation. | G2: =IFERROR(__xludf.DUMMYFUNCTION("GEMINI(""Explain in 1 sentence how §168 impacts ratios like Effective Tax Rate or R&D Intensity. For a non-accountant CFO. Text: ""&B2)"),"IRC Section 168 provides an immediate 100% bonus depreciation deduction for qualified property, which lowers your taxable income and can significantly reduce your effective tax rate in the year assets are placed in service.") -> IRC Section 168 provides an immediate 100% bonus depreciation deduction for qualified property, which lowers your taxable income and can significantly reduce your effective tax rate in the year assets are placed in service.
A3: §179 | B3: (a)Treatment as expenses A taxpayer may elect to treat the cost of any section 179 property as an expense which is not chargeable to capital account. Any cost so treated shall be allowed as a deduction for the taxable year in which the section 179 property is placed in service. (b)Limitations (1)Dollar limitation The aggregate cost which may be taken into account under subsection (a) for any taxable year shall not exceed $2,500,000. (2)Reduction in limitation The limitation under paragraph (1) for any taxable year shall be reduced (but not below zero) by the amount by which the cost of section 179 property placed in service during such taxable year exceeds $4,000,000. (3)Limitation based on income from trade or business (A)In general The amount allowed as a deduction under subsection (a) for any taxable year (determined after the application of paragraphs (1) and (2)) shall not exceed the aggregate amount of taxable income of the taxpayer for such taxable year which is derived from the active conduct by the taxpayer of any trade or business during such taxable year. (B)Carryover of disallowed deduction The amount allowable as a deduction under subsection (a) for any taxable year shall be increased by the lesser of— (i)the aggregate amount disallowed under subparagraph (A) for all prior taxable years (to the extent not previously allowed as a deduction by reason of this subparagraph), or (ii)the excess (if any) of— (I)the limitation of paragraphs (1) and (2) (or if lesser, the aggregate amount of taxable income referred to in subparagraph (A)), over (II)the amount allowable as a deduction under subsection (a) for such taxable year without regard to this subparagraph. (C)Computation of taxable income For purposes of this paragraph, taxable income derived from the conduct of a trade or business shall be computed without regard to the deduction allowable under this section. (4)Married individuals filing separately In the case of a husband and wife filing separate returns for the taxable year— (A)such individuals shall be treated as 1 taxpayer for purposes of paragraphs (1) and (2), and (B)unless such individuals elect otherwise, 50 percent of the cost which may be taken into account under subsection (a) for such taxable year (before application of paragraph (3)) shall be allocated to each such individual. (5)Limitation on cost taken into account for certain passenger vehicles (A)In general The cost of any sport utility vehicle for any taxable year which may be taken into account under this section shall not exceed $25,000. (B)Sport utility vehicle For purposes of subparagraph (A)— (i)In general The term “sport utility vehicle” means any 4-wheeled vehicle— (I)which is primarily designed or which can be used to carry passengers over public streets, roads, or highways (except any vehicle operated exclusively on a rail or rails), (II)which is not subject to section 280F, and (III)which is rated at not more than 14,000 pounds gross vehicle weight. (ii)Certain vehicles excluded Such term does not include any vehicle which— (I)is designed to have a seating capacity of more than 9 persons behind the driver’s seat, (II)is equipped with a cargo area of at least 6 feet in interior length which is an open area or is designed for use as an open area but is enclosed by a cap and is not readily accessible directly from the passenger compartment, or (III)has an integral enclosure, fully enclosing the driver compartment and load carrying device, does not have seating rearward of the driver’s seat, and has no body section protruding more than 30 inches ahead of the leading edge of the windshield. (6)Inflation adjustment (A)In general In the case of any taxable year beginning after 2018 (2025 in the case of the dollar amounts in paragraphs (1) and (2)), the dollar amounts in paragraphs (1), (2), and (5)(A) shall each be increased by an amount equal to— (i)such dollar amount, multiplied by (ii)the cost-of-living adjustment determined under section 1(f)(3) for the calendar year in which the taxable year begins, determined by substituting in subparagraph (A)(ii) thereof— (I)in the case of amounts in paragraphs (1) and (2), “calendar year 2024” for “calendar year 2016”, and (II)in the case of the amount in paragraph (5)(A), “calendar year 2017” for “calendar year 2016”. (B)Rounding The amount of any increase under subparagraph (A) shall be rounded to the nearest multiple of $10,000 ($100 in the case of any increase in the amount under paragraph (5)(A)). (c)Election (1)In general An election under this section for any taxable year shall— (A)specify the items of section 179 property to which the election applies and the portion of the cost of each of such items which is to be taken into account under subsection (a), and (B)be made on the taxpayer’s return of the tax imposed by this chapter for the taxable year. Such election shall be made in such manner as the Secretary may by regulations prescribe. (2)Election Any election made under this section, and any specification contained in any such election, may be revoked by the taxpayer with respect to any property, and such revocation, once made, shall be irrevocable. (d)Definitions and special rules (1)Section 179 property For purposes of this section, the term “section 179 property” means property— (A)which is— (i)tangible property (to which section 168 applies), or (ii)computer software (as defined in section 197(e)(3)(B)) which is described in section 197(e)(3)(A)(i) and to which section 167 applies, (B)which is— (i)section 1245 property (as defined in section 1245(a)(3)), or (ii)at the election of the taxpayer, qualified real property (as defined in subsection (e)), and (C)which is acquired by purchase for use in the active conduct of a trade or business. Such term shall not include any property described in section 50(b) (other than paragraph (2) thereof). (2)Purchase defined For purposes of paragraph (1), the term “purchase” means any acquisition of property, but only if— (A)the property is not acquired from a person whose relationship to the person acquiring it would result in the disallowance of losses under section 267 or 707(b) (but, in applying section 267(b) and (c) for purposes of this section, paragraph (4) of section 267(c) shall be treated as providing that the family of an individual shall include only his spouse, ancestors, and lineal descendants), (B)the property is not acquired by one component member of a controlled group from another component member of the same controlled group, and (C)the basis of the property in the hands of the person acquiring it is not determined— (i)in whole or in part by reference to the adjusted basis of such property in the hands of the person from whom acquired, or (ii)under section 1014(a) (relating to property acquired from a decedent). (3)Cost For purposes of this section, the cost of property does not include so much of the basis of such property as is determined by reference to the basis of other property held at any time by the person acquiring such property. (4)Section not to apply to estates and trusts This section shall not apply to estates and trusts. (5)Section not to apply to certain noncorporate lessors This section shall not apply to any section 179 property which is purchased by a person who is not a corporation and with respect to which such person is the lessor unless— (A)the property subject to the lease has been manufactured or produced by the lessor, or (B)the term of the lease (taking into account options to renew) is less than 50 percent of the class life of the property (as defined in section 168(i)(1)), and for the period consisting of the first 12 months after the date on which the property is transferred to the lessee the sum of the deductions with respect to such property which are allowable to the lessor solely by reason of section 162 (other than rents and reimbursed amounts with respect to such property) exceeds 15 percent of the rental income produced by such property. (6)Dollar limitation of controlled group For purposes of subsection (b) of this section— (A)all component members of a controlled group shall be treated as one taxpayer, and (B)the Secretary shall apportion the dollar limitation contained in subsection (b)(1) among the component members of such controlled group in such manner as he shall by regulations prescribe. (7)Controlled group defined For purposes of paragraphs (2) and (6), the term “controlled group” has the meaning assigned to it by section 1563(a), except that, for such purposes, the phrase “more than 50 percent” shall be substituted for the phrase “at least 80 percent” each place it appears in section 1563(a)(1). (8)Treatment of partnerships and S corporations In the case of a partnership, the limitations of subsection (b) shall apply with respect to the partnership and with respect to each partner. A similar rule shall apply in the case of an S corporation and its shareholders. (9)Coordination with section 38 No credit shall be allowed under section 38 with respect to any amount for which a deduction is allowed under subsection (a). (10)Recapture in certain cases The Secretary shall, by regulations, provide for recapturing the benefit under any deduction allowable under subsection (a) with respect to any property which is not used predominantly in a trade or business at any time. (e)Qualified real property For purposes of this section, the term “qualified real property” means— (1)any qualified improvement property described in section 168(e)(6), and (2)any of the following improvements to nonresidential real property placed in service after the date such property was first placed in service: (A)Roofs. (B)Heating, ventilation, and air-conditioning property. (C)Fire protection and alarm systems. (D)Security systems. (Added Pub. L. 85–866, title II, § 204(a), Sept. 2, 1958, 72 Stat. 1679; amended Pub. L. 87–834, § 13(c)(2), Oct. 16, 1962, 76 Stat. 1034; Pub. L. 91–172, title IV, § 401(f), Dec. 30, 1969, 83 Stat. 603; Pub. L. 94–455, title II, § 213(a), title XIX, § 1906(b)(13)(A), Oct. 4, 1976, 90 Stat. 1547, 1834; Pub. L. 97–34, title II, § 202(a), Aug. 13, 1981, 95 Stat. 219; Pub. L. 97–354, § 3(f), Oct. 19, 1982, 96 Stat. 1689; Pub. L. 97–448, title I, § 102(aa), Jan. 12, 1983, 96 Stat. 2369; Pub. L. 98–369, div. A, title I, § 13, July 18, 1984, 98 Stat. 505; Pub. L. 99–514, title II, §§ 201(d)(3), 202, Oct. 22, 1986, 100 Stat. 2139, 2142; Pub. L. 100–647, title I, § 1002(a)(19), (b)(1), Nov. 10, 1988, 102 Stat. 3356, 3357; Pub. L. 101–508, title XI, § 11813(b)(11), Nov. 5, 1990, 104 Stat. 1388–554; Pub. L. 103–66, title XIII, § 13116(a), Aug. 10, 1993, 107 Stat. 432; Pub. L. 104–188, title I, §§ 1111(a), 1702(h)(10), (19), Aug. 20, 1996, 110 Stat. 1758, 1874; Pub. L. 108–27, title II, § 202(a)–(e), May 28, 2003, 117 Stat. 757, 758; Pub. L. 108–357, title II, § 201, title VIII, § 910(a), Oct. 22, 2004, 118 Stat. 1429, 1659; Pub. L. 109–222, title I, § 101, May 17, 2006, 120 Stat. 346; Pub. L. 110–28, title VIII, § 8212(a)–(c), May 25, 2007, 121 Stat. 192; Pub. L. 110–185, title I, § 102(a), Feb. 13, 2008, 122 Stat. 618; Pub. L. 110–343, div. C, title VII, § 711(a), Oct. 3, 2008, 122 Stat. 3928; Pub. L. 111–5, div. B, title I, § 1202(a), Feb. 17, 2009, 123 Stat. 335; Pub. L. 111–147, title II, § 201(a), Mar. 18, 2010, 124 Stat. 77; Pub. L. 111–240, title II, § 2021(a)–(d), Sept. 27, 2010, 124 Stat. 2556, 2558; Pub. L. 111–312, title IV, § 402(a)–(e), title VII, § 737(b)(3), Dec. 17, 2010, 124 Stat. 3306, 3307, 3318; Pub. L. 112–240, title III, § 315(a)–(d), Jan. 2, 2013, 126 Stat. 2330, 2331; Pub. L. 113–295, div. A, title I, § 127(a)–(d), Dec. 19, 2014, 128 Stat. 4017; Pub. L. 114–113, div. Q, title I, § 124(a)–(f), Dec. 18, 2015, 129 Stat. 3053; Pub. L. 115–97, title I, §§ 11002(d)(1)(R), 13101(a)–(c), Dec. 22, 2017, 131 Stat. 2060, 2101, 2102; Pub. L. 115–141, div. U, title IV, § 401(b)(15)(A), (B), Mar. 23, 2018, 132 Stat. 1202; Pub. L. 119–21, title VII, § 70306(a), (b), July 4, 2025, 139 Stat. 197.) | C3: =IFERROR(__xludf.DUMMYFUNCTION("GEMINI(""Summarize IRC §41 in exactly 1 sentence under 20 words. Focus on who qualifies and the credit value. Text: ""&B3)"),"Businesses can immediately deduct the full cost of qualifying equipment and software instead of depreciating it over time.") -> Businesses can immediately deduct the full cost of qualifying equipment and software instead of depreciating it over time. | D3: =IFERROR(__xludf.DUMMYFUNCTION("GEMINI(""List 3-5 industries and 2-3 entity types most affected. Format exactly: Industries: [x,y,z] | Entities: [a,b,c]. Text: ""&B3)"),"Industries: [Motion Picture and Video, Sound Recording, Performing Arts, Agriculture, Transportation] | Entities: [Corporations, Limited Liability Companies, Partnerships]") -> Industries: [Motion Picture and Video, Sound Recording, Performing Arts, Agriculture, Transportation] | Entities: [Corporations, Limited Liability Companies, Partnerships] | E3: =IFERROR(__xludf.DUMMYFUNCTION("GEMINI(""What QuickBooks data fields check if §41 applies? List comma-separated account names or report fields. Text: ""&B3)"),"Fixed Asset Accounts, Purchase Date, Asset Description, Original Cost, Accumulated Depreciation, Section 179/Bonus Depreciation Election, Chart of Accounts (for business type and floor plan financing interest), Vehicle Log (for 280F compliance), Item List"&" (for computer software or media productions)") -> Fixed Asset Accounts, Purchase Date, Asset Description, Original Cost, Accumulated Depreciation, Section 179/Bonus Depreciation Election, Chart of Accounts (for business type and floor plan financing interest), Vehicle Log (for 280F compliance), Item List (for computer software or media productions) | F3: 🚨 Important: Section 179 Expensing Update for [Entity] How this affects you: Great news for [Year]! Based on your [R&D_Spend] in qualifying property investments, your business could be eligible for a significant tax deduction. We estimate your potential credit at [Credit_Estimate]. This incentive allows [Entity] to treat the cost of qualifying section 179 property—like equipment, software, and certain real property improvements—as an immediate expense rather than a capital charge. For the [Year] taxable year, you can deduct up to $2,500,000 of the adjusted basis for assets placed in service this year. ✅ File Form 6765 to elect and claim your specific section 179 deductions ✅ Schedule a CPA review to ensure your property meet "active conduct of trade or business" requirements ✅ Update your QuickBooks tagging for all fixed assets to automate tracking and compliance 📚 Source: IRC Section 179 ⚠️ Disclaimer: This template is for informational purposes only. Tax laws are subject to change and individual circumstances vary. Please consult with a qualified tax professional to confirm eligibility and compliance for your specific entity. | G3: =IFERROR(__xludf.DUMMYFUNCTION("GEMINI(""Explain in 1 sentence how §179 impacts ratios like Effective Tax Rate or R&D Intensity. For a non-accountant CFO. Text: ""&B3)"),"IRC Section 179 provides an immediate deduction for equipment and software costs, which lowers taxable income and reduces your effective tax rate in the year these assets are placed in service.") -> IRC Section 179 provides an immediate deduction for equipment and software costs, which lowers taxable income and reduces your effective tax rate in the year these assets are placed in service.
A4: §41 | B4: §41(a): A credit is allowed against tax for increasing research activities. Qualified research expenses include wages, supplies, and contract research. Credit rate: 20% of current QREs over base amount, or 14% of QREs for alternative simplified credit. Startups may elect to apply up to $500K against payroll tax. | C4: =IFERROR(__xludf.DUMMYFUNCTION("GEMINI(""Summarize IRC §41 in exactly 1 sentence under 20 words. Focus on who qualifies and the credit value. Text: ""&B4)"),"Businesses and startups qualify for a tax credit worth 14% to 20% of qualified research expenses.") -> Businesses and startups qualify for a tax credit worth 14% to 20% of qualified research expenses. | D4: =IFERROR(__xludf.DUMMYFUNCTION("GEMINI(""List 3-5 industries and 2-3 entity types most affected. Format exactly: Industries: [x,y,z] | Entities: [a,b,c]. Text: ""&B4)"),"Industries: [Technology, Life Sciences, Manufacturing, Biotechnology, Aerospace] | Entities: [Corporations, Partnerships, Limited Liability Companies]") -> Industries: [Technology, Life Sciences, Manufacturing, Biotechnology, Aerospace] | Entities: [Corporations, Partnerships, Limited Liability Companies] | E4: =IFERROR(__xludf.DUMMYFUNCTION("GEMINI(""What QuickBooks data fields check if §41 applies? List comma-separated account names or report fields. Text: ""&B4)"),"Payroll Expenses (Wages), Supplies Expense, Contractor/Consultant Fees, R&D Expense (Class/Account), Employee Time Tracking/Timesheets, Project Name, Project Description, Purchase Orders, Vendor Invoices, Form 941 (Payroll Tax), Gross Receipts (Sales)") -> Payroll Expenses (Wages), Supplies Expense, Contractor/Consultant Fees, R&D Expense (Class/Account), Employee Time Tracking/Timesheets, Project Name, Project Description, Purchase Orders, Vendor Invoices, Form 941 (Payroll Tax), Gross Receipts (Sales) | F4: 🚨 Important: Research & Development Tax Credit for [Entity] How this affects you: Great news for [Year]\! Based on your [R&D_Spend] in qualified research expenses, your business could be eligible for a significant tax credit. We estimate your potential credit at [Credit_Estimate]. This incentive is designed to reward your innovation by allowing you to claim a credit for wages, supplies, and contract research, helping you reinvest in your company's growth. ✅ Ensure all qualified expenses are properly documented for Form 6765 ✅ Schedule a CPA review to verify your eligibility and maximize your credit ✅ Confirm that all R\&D-related transactions are correctly tagged in QuickBooks 📚 Source: IRC Section 41 ⚠️ Disclaimer: This template is for informational purposes only. Tax laws are subject to change and individual circumstances vary. Please consult with a qualified tax professional to confirm eligibility and compliance for your specific entity. | G4: =IFERROR(__xludf.DUMMYFUNCTION("GEMINI(""Explain in 1 sentence how §41 impacts ratios like Effective Tax Rate or R&D Intensity. For a non-accountant CFO. Text: ""&B4)"),"IRC Section 41 provides a dollar-for-dollar credit that directly reduces your effective tax rate while incentivizing a higher R&D intensity by lowering the after-tax cost of innovation.") -> IRC Section 41 provides a dollar-for-dollar credit that directly reduces your effective tax rate while incentivizing a higher R&D intensity by lowering the after-tax cost of innovation.
A5: §3121 | B5: Defines wages for FICA tax purposes. For 2026, the Social Security wage base limit is $184,500. Wages above this are exempt from the 6.2% Social Security tax. | C5: =IFERROR(__xludf.DUMMYFUNCTION("GEMINI(""Summarize IRC §3121 in exactly 1 sentence under 20 words. Focus on the FICA wage base limit and who it affects. Text: ""&B5)"),"IRC §3121 limits FICA taxes to the first $184,500 of an employee's wages in 2026.") -> IRC §3121 limits FICA taxes to the first $184,500 of an employee's wages in 2026. | D5: =IFERROR(__xludf.DUMMYFUNCTION("GEMINI(""List 3-5 industries and 2-3 entity types most affected. Format exactly: Industries: [x,y,z] | Entities: [a,b,c]. Text: ""&B5)"),"Industries: [Technology, Professional Services, Finance, Healthcare, Manufacturing] | Entities: [Corporations, Limited Liability Companies, Partnerships]") -> Industries: [Technology, Professional Services, Finance, Healthcare, Manufacturing] | Entities: [Corporations, Limited Liability Companies, Partnerships] | E5: =IFERROR(__xludf.DUMMYFUNCTION("GEMINI(""What QuickBooks data fields check if §3121 applies? List comma-separated payroll fields or reports. Text: ""&B5)"),"Payroll Expenses: Wages, Payroll Expenses: Taxes, Payroll Liabilities: Federal Taxes (941/944), Employee Profile (Tax Withholding), Payroll Item List, Payroll Summary Report, Payroll Tax and Wage Summary Report, Taxable Wage Audit Report, W-2 Forms") -> Payroll Expenses: Wages, Payroll Expenses: Taxes, Payroll Liabilities: Federal Taxes (941/944), Employee Profile (Tax Withholding), Payroll Item List, Payroll Summary Report, Payroll Tax and Wage Summary Report, Taxable Wage Audit Report, W-2 Forms | F5: 🚨 Important: FICA Wage Base Limit Update for [Entity] How this affects you: For the 2026 tax year, the Social Security wage base is set at [Wage_Base]. This means that for your [Employee_Count] employees, any wages paid above this threshold are exempt from the 6.2% Social Security tax. Once an employee's year-to-date earnings surpass this limit, you should stop withholding the 6.2% employee portion and stop paying the 6.2% employer portion for the remainder of the year. ✅ Perform a payroll review to identify employees approaching the [Wage_Base] limit ✅ Verify that year-to-end W-2 wage reporting correctly reflects the Social Security cap ✅ Ensure all high-earner payroll items are correctly tagged in QuickBooks for accurate tax tracking 📚 Source: IRC Section 3121 ⚠️ Disclaimer: This template is for informational purposes only. Tax laws are subject to change and individual circumstances vary. Please consult with a qualified tax professional to confirm eligibility and compliance for your specific entity. | G5: =IFERROR(__xludf.DUMMYFUNCTION("GEMINI(""Explain in 1 sentence how §3121 impacts cash flow or payroll tax ratios. For a non-accountant CFO. Text: ""&B5)"),"IRC Section 3121 improves cash flow and lowers your effective payroll tax ratio by exempting employee wages above $184,500 from the 6.2% Social Security tax.") -> IRC Section 3121 improves cash flow and lowers your effective payroll tax ratio by exempting employee wages above $184,500 from the 6.2% Social Security tax.
